Workbook

Sheet Planilha1
A1: id | B1: tipo_norma | C1: cod_norma | D1: num_norma | E1: data_assinatura | F1: titulo | G1: ementa | H1: ano | I1: legisltura | J1: status | K1: autor | L1: subcategoria | M1: categoria | N1: tema | O1: palavra-chave | P1: fonte_publicacao | Q1: data_publicação | R1: edicao_publicacao | S1: pagina_publicacao | T1: link_publicacao | U1: pasta | V1: link_consolidado | W1: portal_compi | X1: link_compilado | Y1: portal_conso | Z1: obs
B2: Lei Orgânica | C2: =VLOOKUP(B2,Planilha2!$B$2:$C$100,2,FALSE) -> LOM | D2: 0 | E2: 32968 | F2: LEI ORGÂNICA DO MUNICÍPIO DE MARICÁ, DE 10 DE OUTUBRO DE 1990. | H2: =YEAR(E2) -> 1990 | I2: =VLOOKUP(H2,Planilha2!$E$1:$F$100,2,FALSE) -> 1989-1992 | J2: Em vigor | L2: Emenda à Lei Orgânica | M2: =VLOOKUP(L2,Planilha2!$I$2:$K$100,2,FALSE) -> Lei Orgânica e Regimento Interno | N2: =VLOOKUP(L2,Planilha2!$I$2:$K$100,3,FALSE) -> Organização e Normas Gerais | U2: =VLOOKUP(B2,Planilha2!$B$2:$D$100,3,FALSE) -> lei-organica | V2: ="/legislatura/" & I2 & "/" & H2 & "/" & U2 & "/" & C2 & "-" & TEXT(D2,"00000") & "-" & H2 & ".md" -> /legislatura/1989-1992/1990/lei-organica/LOM-00000-1990.md | X2: ="/legislatura/" & I2 & "/" & H2 & "/" & U2 & "/" & C2 & "-" & TEXT(D2,"00000") & "-" & H2 & "c.md" -> /legislatura/1989-1992/1990/lei-organica/LOM-00000-1990c.md
B3: Emenda à Lei Orgânica | C3: =VLOOKUP(B3,Planilha2!$B$2:$C$100,2,FALSE) -> ELO | D3: 1 | E3: 33156 | F3: EMENDA À LEI ORGÂNICA DO MUNICÍPIO DE MARICÁ Nº 001, DE 10 DE OUTUBRO DE 1990. | H3: =YEAR(E3) -> 1990 | I3: =VLOOKUP(H3,Planilha2!$E$1:$F$100,2,FALSE) -> 1989-1992 | J3: Em vigor | L3: Emenda à Lei Orgânica | M3: =VLOOKUP(L3,Planilha2!$I$2:$K$100,2,FALSE) -> Lei Orgânica e Regimento Interno | N3: =VLOOKUP(L3,Planilha2!$I$2:$K$100,3,FALSE) -> Organização e Normas Gerais | U3: =VLOOKUP(B3,Planilha2!$B$2:$D$100,3,FALSE) -> lei-organica | V3: ="/legislatura/" & I3 & "/" & H3 & "/" & U3 & "/" & C3 & "-" & TEXT(D3,"00000") & "-" & H3 & ".md" -> /legislatura/1989-1992/1990/lei-organica/ELO-00001-1990.md | X3: ="/legislatura/" & I3 & "/" & H3 & "/" & U3 & "/" & C3 & "-" & TEXT(D3,"00000") & "-" & H3 & "c.md" -> /legislatura/1989-1992/1990/lei-organica/ELO-00001-1990c.md
B4: Emenda à Lei Orgânica | C4: =VLOOKUP(B4,Planilha2!$B$2:$C$100,2,FALSE) -> ELO | D4: 2 | E4: 33330 | F4: EMENDA À LEI ORGÂNICA DO MUNICÍPIO DE MARICÁ, Nº 002 DE 02 DE ABRIL DE 1991. | H4: =YEAR(E4) -> 1991 | I4: =VLOOKUP(H4,Planilha2!$E$1:$F$100,2,FALSE) -> 1989-1992 | J4: Em vigor | L4: Emenda à Lei Orgânica | M4: =VLOOKUP(L4,Planilha2!$I$2:$K$100,2,FALSE) -> Lei Orgânica e Regimento Interno | N4: =VLOOKUP(L4,Planilha2!$I$2:$K$100,3,FALSE) -> Organização e Normas Gerais | U4: =VLOOKUP(B4,Planilha2!$B$2:$D$100,3,FALSE) -> lei-organica | V4: ="/legislatura/" & I4 & "/" & H4 & "/" & U4 & "/" & C4 & "-" & TEXT(D4,"00000") & "-" & H4 & ".md" -> /legislatura/1989-1992/1991/lei-organica/ELO-00002-1991.md | X4: ="/legislatura/" & I4 & "/" & H4 & "/" & U4 & "/" & C4 & "-" & TEXT(D4,"00000") & "-" & H4 & "c.md" -> /legislatura/1989-1992/1991/lei-organica/ELO-00002-1991c.md
B5: Emenda à Lei Orgânica | C5: =VLOOKUP(B5,Planilha2!$B$2:$C$100,2,FALSE) -> ELO | D5: 3 | E5: 34033 | F5: EMENDA À LEI ORGÂNICA DO MUNICÍPIO DE MARICÁ, Nº 003 DE 05 DE MARÇO DE 1992. | H5: =YEAR(E5) -> 1993 | I5: =VLOOKUP(H5,Planilha2!$E$1:$F$100,2,FALSE) -> 1993-1996 | J5: Em vigor | L5: Emenda à Lei Orgânica | M5: =VLOOKUP(L5,Planilha2!$I$2:$K$100,2,FALSE) -> Lei Orgânica e Regimento Interno | N5: =VLOOKUP(L5,Planilha2!$I$2:$K$100,3,FALSE) -> Organização e Normas Gerais | U5: =VLOOKUP(B5,Planilha2!$B$2:$D$100,3,FALSE) -> lei-organica | V5: ="/legislatura/" & I5 & "/" & H5 & "/" & U5 & "/" & C5 & "-" & TEXT(D5,"00000") & "-" & H5 & ".md" -> /legislatura/1993-1996/1993/lei-organica/ELO-00003-1993.md | X5: ="/legislatura/" & I5 & "/" & H5 & "/" & U5 & "/" & C5 & "-" & TEXT(D5,"00000") & "-" & H5 & "c.md" -> /legislatura/1993-1996/1993/lei-organica/ELO-00003-1993c.md
B6: Emenda à Lei Orgânica | C6: =VLOOKUP(B6,Planilha2!$B$2:$C$100,2,FALSE) -> ELO | D6: 4 | E6: 34272 | F6: EMENDA À LEI ORGÂNICA DO MUNICÍPIO DE MARICÁ, Nº 004 DE 30 DE SETEMBRO DE 1993. | H6: =YEAR(E6) -> 1993 | I6: =VLOOKUP(H6,Planilha2!$E$1:$F$100,2,FALSE) -> 1993-1996 | J6: Em vigor | L6: Emenda à Lei Orgânica | M6: =VLOOKUP(L6,Planilha2!$I$2:$K$100,2,FALSE) -> Lei Orgânica e Regimento Interno | N6: =VLOOKUP(L6,Planilha2!$I$2:$K$100,3,FALSE) -> Organização e Normas Gerais | U6: =VLOOKUP(B6,Planilha2!$B$2:$D$100,3,FALSE) -> lei-organica | V6: ="/legislatura/" & I6 & "/" & H6 & "/" & U6 & "/" & C6 & "-" & TEXT(D6,"00000") & "-" & H6 & ".md" -> /legislatura/1993-1996/1993/lei-organica/ELO-00004-1993.md | X6: ="/legislatura/" & I6 & "/" & H6 & "/" & U6 & "/" & C6 & "-" & TEXT(D6,"00000") & "-" & H6 & "c.md" -> /legislatura/1993-1996/1993/lei-organica/ELO-00004-1993c.md
B7: Emenda à Lei Orgânica | C7: =VLOOKUP(B7,Planilha2!$B$2:$C$100,2,FALSE) -> ELO | D7: 5 | E7: 34319 | F7: EMENDA À LEI ORGÂNICA DO MUNICÍPIO DE MARICÁ, Nº 005 DE 16 DE DEZEMBRO DE 1993. | H7: =YEAR(E7) -> 1993 | I7: =VLOOKUP(H7,Planilha2!$E$1:$F$100,2,FALSE) -> 1993-1996 | J7: Em vigor | L7: Emenda à Lei Orgânica | M7: =VLOOKUP(L7,Planilha2!$I$2:$K$100,2,FALSE) -> Lei Orgânica e Regimento Interno | N7: =VLOOKUP(L7,Planilha2!$I$2:$K$100,3,FALSE) -> Organização e Normas Gerais | U7: =VLOOKUP(B7,Planilha2!$B$2:$D$100,3,FALSE) -> lei-organica | V7: ="/legislatura/" & I7 & "/" & H7 & "/" & U7 & "/" & C7 & "-" & TEXT(D7,"00000") & "-" & H7 & ".md" -> /legislatura/1993-1996/1993/lei-organica/ELO-00005-1993.md | X7: ="/legislatura/" & I7 & "/" & H7 & "/" & U7 & "/" & C7 & "-" & TEXT(D7,"00000") & "-" & H7 & "c.md" -> /legislatura/1993-1996/1993/lei-organica/ELO-00005-1993c.md
B8: Emenda à Lei Orgânica | C8: =VLOOKUP(B8,Planilha2!$B$2:$C$100,2,FALSE) -> ELO | D8: 6 | H8: =YEAR(E8) -> 1900 | I8: =VLOOKUP(H8,Planilha2!$E$1:$F$100,2,FALSE) -> #N/A | J8: Em vigor | L8: Emenda à Lei Orgânica | M8: =VLOOKUP(L8,Planilha2!$I$2:$K$100,2,FALSE) -> Lei Orgânica e Regimento Interno | N8: =VLOOKUP(L8,Planilha2!$I$2:$K$100,3,FALSE) -> Organização e Normas Gerais | U8: =VLOOKUP(B8,Planilha2!$B$2:$D$100,3,FALSE) -> lei-organica | V8: ="/legislatura/" & I8 & "/" & H8 & "/" & U8 & "/" & C8 & "-" & TEXT(D8,"00000") & "-" & H8 & ".md" -> #N/A | X8: ="/legislatura/" & I8 & "/" & H8 & "/" & U8 & "/" & C8 & "-" & TEXT(D8,"00000") & "-" & H8 & "c.md" -> #N/A
B9: Emenda à Lei Orgânica | C9: =VLOOKUP(B9,Planilha2!$B$2:$C$100,2,FALSE) -> ELO | D9: 7 | H9: =YEAR(E9) -> 1900 | I9: =VLOOKUP(H9,Planilha2!$E$1:$F$100,2,FALSE) -> #N/A | J9: Em vigor | L9: Emenda à Lei Orgânica | M9: =VLOOKUP(L9,Planilha2!$I$2:$K$100,2,FALSE) -> Lei Orgânica e Regimento Interno | N9: =VLOOKUP(L9,Planilha2!$I$2:$K$100,3,FALSE) -> Organização e Normas Gerais | U9: =VLOOKUP(B9,Planilha2!$B$2:$D$100,3,FALSE) -> lei-organica | V9: ="/legislatura/" & I9 & "/" & H9 & "/" & U9 & "/" & C9 & "-" & TEXT(D9,"00000") & "-" & H9 & ".md" -> #N/A | X9: ="/legislatura/" & I9 & "/" & H9 & "/" & U9 & "/" & C9 & "-" & TEXT(D9,"00000") & "-" & H9 & "c.md" -> #N/A
B10: Emenda à Lei Orgânica | C10: =VLOOKUP(B10,Planilha2!$B$2:$C$100,2,FALSE) -> ELO | D10: 8 | H10: =YEAR(E10) -> 1900 | I10: =VLOOKUP(H10,Planilha2!$E$1:$F$100,2,FALSE) -> #N/A | J10: Em vigor | L10: Emenda à Lei Orgânica | M10: =VLOOKUP(L10,Planilha2!$I$2:$K$100,2,FALSE) -> Lei Orgânica e Regimento Interno | N10: =VLOOKUP(L10,Planilha2!$I$2:$K$100,3,FALSE) -> Organização e Normas Gerais | U10: =VLOOKUP(B10,Planilha2!$B$2:$D$100,3,FALSE) -> lei-organica | V10: ="/legislatura/" & I10 & "/" & H10 & "/" & U10 & "/" & C10 & "-" & TEXT(D10,"00000") & "-" & H10 & ".md" -> #N/A | X10: ="/legislatura/" & I10 & "/" & H10 & "/" & U10 & "/" & C10 & "-" & TEXT(D10,"00000") & "-" & H10 & "c.md" -> #N/A
B11: Emenda à Lei Orgânica | C11: =VLOOKUP(B11,Planilha2!$B$2:$C$100,2,FALSE) -> ELO | D11: 9 | H11: =YEAR(E11) -> 1900 | I11: =VLOOKUP(H11,Planilha2!$E$1:$F$100,2,FALSE) -> #N/A | J11: Em vigor | L11: Emenda à Lei Orgânica | M11: =VLOOKUP(L11,Planilha2!$I$2:$K$100,2,FALSE) -> Lei Orgânica e Regimento Interno | N11: =VLOOKUP(L11,Planilha2!$I$2:$K$100,3,FALSE) -> Organização e Normas Gerais | U11: =VLOOKUP(B11,Planilha2!$B$2:$D$100,3,FALSE) -> lei-organica | V11: ="/legislatura/" & I11 & "/" & H11 & "/" & U11 & "/" & C11 & "-" & TEXT(D11,"00000") & "-" & H11 & ".md" -> #N/A | X11: ="/legislatura/" & I11 & "/" & H11 & "/" & U11 & "/" & C11 & "-" & TEXT(D11,"00000") & "-" & H11 & "c.md" -> #N/A
B12: Emenda à Lei Orgânica | C12: =VLOOKUP(B12,Planilha2!$B$2:$C$100,2,FALSE) -> ELO | D12: 10 | H12: =YEAR(E12) -> 1900 | I12: =VLOOKUP(H12,Planilha2!$E$1:$F$100,2,FALSE) -> #N/A | J12: Em vigor | L12: Emenda à Lei Orgânica | M12: =VLOOKUP(L12,Planilha2!$I$2:$K$100,2,FALSE) -> Lei Orgânica e Regimento Interno | N12: =VLOOKUP(L12,Planilha2!$I$2:$K$100,3,FALSE) -> Organização e Normas Gerais | U12: =VLOOKUP(B12,Planilha2!$B$2:$D$100,3,FALSE) -> lei-organica | V12: ="/legislatura/" & I12 & "/" & H12 & "/" & U12 & "/" & C12 & "-" & TEXT(D12,"00000") & "-" & H12 & ".md" -> #N/A | X12: ="/legislatura/" & I12 & "/" & H12 & "/" & U12 & "/" & C12 & "-" & TEXT(D12,"00000") & "-" & H12 & "c.md" -> #N/A
B13: Emenda à Lei Orgânica | C13: =VLOOKUP(B13,Planilha2!$B$2:$C$100,2,FALSE) -> ELO | D13: 11 | H13: =YEAR(E13) -> 1900 | I13: =VLOOKUP(H13,Planilha2!$E$1:$F$100,2,FALSE) -> #N/A | J13: Em vigor | L13: Emenda à Lei Orgânica | M13: =VLOOKUP(L13,Planilha2!$I$2:$K$100,2,FALSE) -> Lei Orgânica e Regimento Interno | N13: =VLOOKUP(L13,Planilha2!$I$2:$K$100,3,FALSE) -> Organização e Normas Gerais | U13: =VLOOKUP(B13,Planilha2!$B$2:$D$100,3,FALSE) -> lei-organica | V13: ="/legislatura/" & I13 & "/" & H13 & "/" & U13 & "/" & C13 & "-" & TEXT(D13,"00000") & "-" & H13 & ".md" -> #N/A | X13: ="/legislatura/" & I13 & "/" & H13 & "/" & U13 & "/" & C13 & "-" & TEXT(D13,"00000") & "-" & H13 & "c.md" -> #N/A
B14: Emenda à Lei Orgânica | C14: =VLOOKUP(B14,Planilha2!$B$2:$C$100,2,FALSE) -> ELO | D14: 12 | H14: =YEAR(E14) -> 1900 | I14: =VLOOKUP(H14,Planilha2!$E$1:$F$100,2,FALSE) -> #N/A | J14: Em vigor | L14: Emenda à Lei Orgânica | M14: =VLOOKUP(L14,Planilha2!$I$2:$K$100,2,FALSE) -> Lei Orgânica e Regimento Interno | N14: =VLOOKUP(L14,Planilha2!$I$2:$K$100,3,FALSE) -> Organização e Normas Gerais | U14: =VLOOKUP(B14,Planilha2!$B$2:$D$100,3,FALSE) -> lei-organica | V14: ="/legislatura/" & I14 & "/" & H14 & "/" & U14 & "/" & C14 & "-" & TEXT(D14,"00000") & "-" & H14 & ".md" -> #N/A | X14: ="/legislatura/" & I14 & "/" & H14 & "/" & U14 & "/" & C14 & "-" & TEXT(D14,"00000") & "-" & H14 & "c.md" -> #N/A
B15: Emenda à Lei Orgânica | C15: =VLOOKUP(B15,Planilha2!$B$2:$C$100,2,FALSE) -> ELO | D15: 13 | H15: =YEAR(E15) -> 1900 | I15: =VLOOKUP(H15,Planilha2!$E$1:$F$100,2,FALSE) -> #N/A | J15: Em vigor | L15: Emenda à Lei Orgânica | M15: =VLOOKUP(L15,Planilha2!$I$2:$K$100,2,FALSE) -> Lei Orgânica e Regimento Interno | N15: =VLOOKUP(L15,Planilha2!$I$2:$K$100,3,FALSE) -> Organização e Normas Gerais | U15: =VLOOKUP(B15,Planilha2!$B$2:$D$100,3,FALSE) -> lei-organica | V15: ="/legislatura/" & I15 & "/" & H15 & "/" & U15 & "/" & C15 & "-" & TEXT(D15,"00000") & "-" & H15 & ".md" -> #N/A | X15: ="/legislatura/" & I15 & "/" & H15 & "/" & U15 & "/" & C15 & "-" & TEXT(D15,"00000") & "-" & H15 & "c.md" -> #N/A
B16: Emenda à Lei Orgânica | C16: =VLOOKUP(B16,Planilha2!$B$2:$C$100,2,FALSE) -> ELO | D16: 14 | H16: =YEAR(E16) -> 1900 | I16: =VLOOKUP(H16,Planilha2!$E$1:$F$100,2,FALSE) -> #N/A | J16: Em vigor | L16: Emenda à Lei Orgânica | M16: =VLOOKUP(L16,Planilha2!$I$2:$K$100,2,FALSE) -> Lei Orgânica e Regimento Interno | N16: =VLOOKUP(L16,Planilha2!$I$2:$K$100,3,FALSE) -> Organização e Normas Gerais | U16: =VLOOKUP(B16,Planilha2!$B$2:$D$100,3,FALSE) -> lei-organica | V16: ="/legislatura/" & I16 & "/" & H16 & "/" & U16 & "/" & C16 & "-" & TEXT(D16,"00000") & "-" & H16 & ".md" -> #N/A | X16: ="/legislatura/" & I16 & "/" & H16 & "/" & U16 & "/" & C16 & "-" & TEXT(D16,"00000") & "-" & H16 & "c.md" -> #N/A
B17: Emenda à Lei Orgânica | C17: =VLOOKUP(B17,Planilha2!$B$2:$C$100,2,FALSE) -> ELO | D17: 15 | E17: 36432 | F17: EMENDA À LEI ORGÂNICA DO MUNICÍPIO DE MARICÁ, Nº 015 DE 29 DE SETEMBRO DE 1999. | G17: Dispõe sobre a revogação do artigo 15 e o seu parágrafo único do Ato das Disposições Transitórias da Lei Orgânica de Maricá. | H17: =YEAR(E17) -> 1999 | I17: =VLOOKUP(H17,Planilha2!$E$1:$F$100,2,FALSE) -> 1997-2000 | J17: Em vigor | L17: Emenda à Lei Orgânica | M17: =VLOOKUP(L17,Planilha2!$I$2:$K$100,2,FALSE) -> Lei Orgânica e Regimento Interno | N17: =VLOOKUP(L17,Planilha2!$I$2:$K$100,3,FALSE) -> Organização e Normas Gerais | P17: Jornal da Região | U17: =VLOOKUP(B17,Planilha2!$B$2:$D$100,3,FALSE) -> lei-organica | V17: ="/legislatura/" & I17 & "/" & H17 & "/" & U17 & "/" & C17 & "-" & TEXT(D17,"00000") & "-" & H17 & ".md" -> /legislatura/1997-2000/1999/lei-organica/ELO-00015-1999.md | X17: ="/legislatura/" & I17 & "/" & H17 & "/" & U17 & "/" & C17 & "-" & TEXT(D17,"00000") & "-" & H17 & "c.md" -> /legislatura/1997-2000/1999/lei-organica/ELO-00015-1999c.md
B18: Emenda à Lei Orgânica | C18: =VLOOKUP(B18,Planilha2!$B$2:$C$100,2,FALSE) -> ELO | D18: 16 | H18: =YEAR(E18) -> 1900 | I18: =VLOOKUP(H18,Planilha2!$E$1:$F$100,2,FALSE) -> #N/A | J18: Em vigor | L18: Emenda à Lei Orgânica | M18: =VLOOKUP(L18,Planilha2!$I$2:$K$100,2,FALSE) -> Lei Orgânica e Regimento Interno | N18: =VLOOKUP(L18,Planilha2!$I$2:$K$100,3,FALSE) -> Organização e Normas Gerais | U18: =VLOOKUP(B18,Planilha2!$B$2:$D$100,3,FALSE) -> lei-organica | V18: ="/legislatura/" & I18 & "/" & H18 & "/" & U18 & "/" & C18 & "-" & TEXT(D18,"00000") & "-" & H18 & ".md" -> #N/A | X18: ="/legislatura/" & I18 & "/" & H18 & "/" & U18 & "/" & C18 & "-" & TEXT(D18,"00000") & "-" & H18 & "c.md" -> #N/A
B19: Emenda à Lei Orgânica | C19: =VLOOKUP(B19,Planilha2!$B$2:$C$100,2,FALSE) -> ELO | D19: 17 | H19: =YEAR(E19) -> 1900 | I19: =VLOOKUP(H19,Planilha2!$E$1:$F$100,2,FALSE) -> #N/A | J19: Em vigor | L19: Emenda à Lei Orgânica | M19: =VLOOKUP(L19,Planilha2!$I$2:$K$100,2,FALSE) -> Lei Orgânica e Regimento Interno | N19: =VLOOKUP(L19,Planilha2!$I$2:$K$100,3,FALSE) -> Organização e Normas Gerais | U19: =VLOOKUP(B19,Planilha2!$B$2:$D$100,3,FALSE) -> lei-organica | V19: ="/legislatura/" & I19 & "/" & H19 & "/" & U19 & "/" & C19 & "-" & TEXT(D19,"00000") & "-" & H19 & ".md" -> #N/A | X19: ="/legislatura/" & I19 & "/" & H19 & "/" & U19 & "/" & C19 & "-" & TEXT(D19,"00000") & "-" & H19 & "c.md" -> #N/A
B20: Emenda à Lei Orgânica | C20: =VLOOKUP(B20,Planilha2!$B$2:$C$100,2,FALSE) -> ELO | D20: 18 | H20: =YEAR(E20) -> 1900 | I20: =VLOOKUP(H20,Planilha2!$E$1:$F$100,2,FALSE) -> #N/A | J20: Em vigor | L20: Emenda à Lei Orgânica | M20: =VLOOKUP(L20,Planilha2!$I$2:$K$100,2,FALSE) -> Lei Orgânica e Regimento Interno | N20: =VLOOKUP(L20,Planilha2!$I$2:$K$100,3,FALSE) -> Organização e Normas Gerais | U20: =VLOOKUP(B20,Planilha2!$B$2:$D$100,3,FALSE) -> lei-organica | V20: ="/legislatura/" & I20 & "/" & H20 & "/" & U20 & "/" & C20 & "-" & TEXT(D20,"00000") & "-" & H20 & ".md" -> #N/A | X20: ="/legislatura/" & I20 & "/" & H20 & "/" & U20 & "/" & C20 & "-" & TEXT(D20,"00000") & "-" & H20 & "c.md" -> #N/A
B21: Emenda à Lei Orgânica | C21: =VLOOKUP(B21,Planilha2!$B$2:$C$100,2,FALSE) -> ELO | D21: 19 | H21: =YEAR(E21) -> 1900 | I21: =VLOOKUP(H21,Planilha2!$E$1:$F$100,2,FALSE) -> #N/A | J21: Em vigor | L21: Emenda à Lei Orgânica | M21: =VLOOKUP(L21,Planilha2!$I$2:$K$100,2,FALSE) -> Lei Orgânica e Regimento Interno | N21: =VLOOKUP(L21,Planilha2!$I$2:$K$100,3,FALSE) -> Organização e Normas Gerais | U21: =VLOOKUP(B21,Planilha2!$B$2:$D$100,3,FALSE) -> lei-organica | V21: ="/legislatura/" & I21 & "/" & H21 & "/" & U21 & "/" & C21 & "-" & TEXT(D21,"00000") & "-" & H21 & ".md" -> #N/A | X21: ="/legislatura/" & I21 & "/" & H21 & "/" & U21 & "/" & C21 & "-" & TEXT(D21,"00000") & "-" & H21 & "c.md" -> #N/A
B22: Emenda à Lei Orgânica | C22: =VLOOKUP(B22,Planilha2!$B$2:$C$100,2,FALSE) -> ELO | D22: 20 | H22: =YEAR(E22) -> 1900 | I22: =VLOOKUP(H22,Planilha2!$E$1:$F$100,2,FALSE) -> #N/A | J22: Em vigor | L22: Emenda à Lei Orgânica | M22: =VLOOKUP(L22,Planilha2!$I$2:$K$100,2,FALSE) -> Lei Orgânica e Regimento Interno | N22: =VLOOKUP(L22,Planilha2!$I$2:$K$100,3,FALSE) -> Organização e Normas Gerais | U22: =VLOOKUP(B22,Planilha2!$B$2:$D$100,3,FALSE) -> lei-organica | V22: ="/legislatura/" & I22 & "/" & H22 & "/" & U22 & "/" & C22 & "-" & TEXT(D22,"00000") & "-" & H22 & ".md" -> #N/A | X22: ="/legislatura/" & I22 & "/" & H22 & "/" & U22 & "/" & C22 & "-" & TEXT(D22,"00000") & "-" & H22 & "c.md" -> #N/A
B23: Emenda à Lei Orgânica | C23: =VLOOKUP(B23,Planilha2!$B$2:$C$100,2,FALSE) -> ELO | D23: 21 | H23: =YEAR(E23) -> 1900 | I23: =VLOOKUP(H23,Planilha2!$E$1:$F$100,2,FALSE) -> #N/A | J23: Em vigor | L23: Emenda à Lei Orgânica | M23: =VLOOKUP(L23,Planilha2!$I$2:$K$100,2,FALSE) -> Lei Orgânica e Regimento Interno | N23: =VLOOKUP(L23,Planilha2!$I$2:$K$100,3,FALSE) -> Organização e Normas Gerais | U23: =VLOOKUP(B23,Planilha2!$B$2:$D$100,3,FALSE) -> lei-organica | V23: ="/legislatura/" & I23 & "/" & H23 & "/" & U23 & "/" & C23 & "-" & TEXT(D23,"00000") & "-" & H23 & ".md" -> #N/A | X23: ="/legislatura/" & I23 & "/" & H23 & "/" & U23 & "/" & C23 & "-" & TEXT(D23,"00000") & "-" & H23 & "c.md" -> #N/A
B24: Emenda à Lei Orgânica | C24: =VLOOKUP(B24,Planilha2!$B$2:$C$100,2,FALSE) -> ELO | D24: 22 | H24: =YEAR(E24) -> 1900 | I24: =VLOOKUP(H24,Planilha2!$E$1:$F$100,2,FALSE) -> #N/A | J24: Em vigor | L24: Emenda à Lei Orgânica | M24: =VLOOKUP(L24,Planilha2!$I$2:$K$100,2,FALSE) -> Lei Orgânica e Regimento Interno | N24: =VLOOKUP(L24,Planilha2!$I$2:$K$100,3,FALSE) -> Organização e Normas Gerais | U24: =VLOOKUP(B24,Planilha2!$B$2:$D$100,3,FALSE) -> lei-organica | V24: ="/legislatura/" & I24 & "/" & H24 & "/" & U24 & "/" & C24 & "-" & TEXT(D24,"00000") & "-" & H24 & ".md" -> #N/A | X24: ="/legislatura/" & I24 & "/" & H24 & "/" & U24 & "/" & C24 & "-" & TEXT(D24,"00000") & "-" & H24 & "c.md" -> #N/A
B25: Emenda à Lei Orgânica | C25: =VLOOKUP(B25,Planilha2!$B$2:$C$100,2,FALSE) -> ELO | D25: 23 | H25: =YEAR(E25) -> 1900 | I25: =VLOOKUP(H25,Planilha2!$E$1:$F$100,2,FALSE) -> #N/A | J25: Em vigor | L25: Emenda à Lei Orgânica | M25: =VLOOKUP(L25,Planilha2!$I$2:$K$100,2,FALSE) -> Lei Orgânica e Regimento Interno | N25: =VLOOKUP(L25,Planilha2!$I$2:$K$100,3,FALSE) -> Organização e Normas Gerais | U25: =VLOOKUP(B25,Planilha2!$B$2:$D$100,3,FALSE) -> lei-organica | V25: ="/legislatura/" & I25 & "/" & H25 & "/" & U25 & "/" & C25 & "-" & TEXT(D25,"00000") & "-" & H25 & ".md" -> #N/A | X25: ="/legislatura/" & I25 & "/" & H25 & "/" & U25 & "/" & C25 & "-" & TEXT(D25,"00000") & "-" & H25 & "c.md" -> #N/A
B26: Emenda à Lei Orgânica | C26: =VLOOKUP(B26,Planilha2!$B$2:$C$100,2,FALSE) -> ELO | D26: 24 | H26: =YEAR(E26) -> 1900 | I26: =VLOOKUP(H26,Planilha2!$E$1:$F$100,2,FALSE) -> #N/A | J26: Em vigor | L26: Emenda à Lei Orgânica | M26: =VLOOKUP(L26,Planilha2!$I$2:$K$100,2,FALSE) -> Lei Orgânica e Regimento Interno | N26: =VLOOKUP(L26,Planilha2!$I$2:$K$100,3,FALSE) -> Organização e Normas Gerais | U26: =VLOOKUP(B26,Planilha2!$B$2:$D$100,3,FALSE) -> lei-organica | V26: ="/legislatura/" & I26 & "/" & H26 & "/" & U26 & "/" & C26 & "-" & TEXT(D26,"00000") & "-" & H26 & ".md" -> #N/A | X26: ="/legislatura/" & I26 & "/" & H26 & "/" & U26 & "/" & C26 & "-" & TEXT(D26,"00000") & "-" & H26 & "c.md" -> #N/A
B27: Emenda à Lei Orgânica | C27: =VLOOKUP(B27,Planilha2!$B$2:$C$100,2,FALSE) -> ELO | D27: 25 | H27: =YEAR(E27) -> 1900 | I27: =VLOOKUP(H27,Planilha2!$E$1:$F$100,2,FALSE) -> #N/A | J27: Em vigor | L27: Emenda à Lei Orgânica | M27: =VLOOKUP(L27,Planilha2!$I$2:$K$100,2,FALSE) -> Lei Orgânica e Regimento Interno | N27: =VLOOKUP(L27,Planilha2!$I$2:$K$100,3,FALSE) -> Organização e Normas Gerais | U27: =VLOOKUP(B27,Planilha2!$B$2:$D$100,3,FALSE) -> lei-organica | V27: ="/legislatura/" & I27 & "/" & H27 & "/" & U27 & "/" & C27 & "-" & TEXT(D27,"00000") & "-" & H27 & ".md" -> #N/A | X27: ="/legislatura/" & I27 & "/" & H27 & "/" & U27 & "/" & C27 & "-" & TEXT(D27,"00000") & "-" & H27 & "c.md" -> #N/A
B28: Emenda à Lei Orgânica | C28: =VLOOKUP(B28,Planilha2!$B$2:$C$100,2,FALSE) -> ELO | D28: 26 | H28: =YEAR(E28) -> 1900 | I28: =VLOOKUP(H28,Planilha2!$E$1:$F$100,2,FALSE) -> #N/A | J28: Em vigor | L28: Emenda à Lei Orgânica | M28: =VLOOKUP(L28,Planilha2!$I$2:$K$100,2,FALSE) -> Lei Orgânica e Regimento Interno | N28: =VLOOKUP(L28,Planilha2!$I$2:$K$100,3,FALSE) -> Organização e Normas Gerais | U28: =VLOOKUP(B28,Planilha2!$B$2:$D$100,3,FALSE) -> lei-organica | V28: ="/legislatura/" & I28 & "/" & H28 & "/" & U28 & "/" & C28 & "-" & TEXT(D28,"00000") & "-" & H28 & ".md" -> #N/A | X28: ="/legislatura/" & I28 & "/" & H28 & "/" & U28 & "/" & C28 & "-" & TEXT(D28,"00000") & "-" & H28 & "c.md" -> #N/A
B29: Emenda à Lei Orgânica | C29: =VLOOKUP(B29,Planilha2!$B$2:$C$100,2,FALSE) -> ELO | D29: 27 | H29: =YEAR(E29) -> 1900 | I29: =VLOOKUP(H29,Planilha2!$E$1:$F$100,2,FALSE) -> #N/A | J29: Em vigor | L29: Emenda à Lei Orgânica | M29: =VLOOKUP(L29,Planilha2!$I$2:$K$100,2,FALSE) -> Lei Orgânica e Regimento Interno | N29: =VLOOKUP(L29,Planilha2!$I$2:$K$100,3,FALSE) -> Organização e Normas Gerais | U29: =VLOOKUP(B29,Planilha2!$B$2:$D$100,3,FALSE) -> lei-organica | V29: ="/legislatura/" & I29 & "/" & H29 & "/" & U29 & "/" & C29 & "-" & TEXT(D29,"00000") & "-" & H29 & ".md" -> #N/A | X29: ="/legislatura/" & I29 & "/" & H29 & "/" & U29 & "/" & C29 & "-" & TEXT(D29,"00000") & "-" & H29 & "c.md" -> #N/A
... B54: Emenda à Lei Orgânica | C54: =VLOOKUP(B54,Planilha2!$B$2:$C$100,2,FALSE) -> ELO | D54: 52 | H54: =YEAR(E54) -> 1900 | I54: =VLOOKUP(H54,Planilha2!$E$1:$F$100,2,FALSE) -> #N/A | J54: Em vigor | L54: Emenda à Lei Orgânica | M54: =VLOOKUP(L54,Planilha2!$I$2:$K$100,2,FALSE) -> Lei Orgânica e Regimento Interno | N54: =VLOOKUP(L54,Planilha2!$I$2:$K$100,3,FALSE) -> Organização e Normas Gerais | U54: =VLOOKUP(B54,Planilha2!$B$2:$D$100,3,FALSE) -> lei-organica | V54: ="/legislatura/" & I54 & "/" & H54 & "/" & U54 & "/" & C54 & "-" & TEXT(D54,"00000") & "-" & H54 & ".md" -> #N/A | X54: ="/legislatura/" & I54 & "/" & H54 & "/" & U54 & "/" & C54 & "-" & TEXT(D54,"00000") & "-" & H54 & "c.md" -> #N/A
B55: Lei Ordinária | C55: =VLOOKUP(B55,Planilha2!$B$2:$C$100,2,FALSE) -> LEI | D55: 2641 | E55: 46002 | F55: LEI Nº 2.641 DE 11 DE DEZEMBRO DE 2015. | G55: Institui o Programa de Renda Básica de Cidadania – RBC no Município de Maricá. | H55: =YEAR(E55) -> 2025 | I55: =VLOOKUP(H55,Planilha2!$E$1:$F$100,2,FALSE) -> 2025-2028 | J55: Em vigor | L55: Assistência Social | M55: =VLOOKUP(L55,Planilha2!$I$2:$K$100,2,FALSE) -> Proteção Social | N55: =VLOOKUP(L55,Planilha2!$I$2:$K$100,3,FALSE) -> Política Social | O55: RBC, Renda Básica | P55: JOM Especial | Q55: 42354 | R55: 622 | U55: =VLOOKUP(B55,Planilha2!$B$2:$D$100,3,FALSE) -> lei-ordinaria | V55: ="/legislatura/" & I55 & "/" & H55 & "/" & U55 & "/" & C55 & "-" & TEXT(D55,"00000") & "-" & H55 & ".md" -> /legislatura/2025-2028/2025/lei-ordinaria/LEI-02641-2025.md | W55: Sim | X55: ="/legislatura/" & I55 & "/" & H55 & "/" & U55 & "/" & C55 & "-" & TEXT(D55,"00000") & "-" & H55 & "c.md" -> /legislatura/2025-2028/2025/lei-ordinaria/LEI-02641-2025c.md | Y55: Não
B56: Lei Ordinária | C56: =VLOOKUP(B56,Planilha2!$B$2:$C$100,2,FALSE) -> LEI | D56: 13 | E56: 28411 | F56: LEI Nº 13, DE 13 DE OUTUBRO DE 1977. | G56: Art. 1º Fica considerado de Utilidade Pública, o IPIRANGA MALHA CLUBE. | H56: =YEAR(E56) -> 1977 | I56: =VLOOKUP(H56,Planilha2!$E$1:$F$100,2,FALSE) -> 1977-1982 | J56: Em vigor | L56: Esportes e Lazer | M56: =VLOOKUP(L56,Planilha2!$I$2:$K$100,2,FALSE) -> Cultura, Esporte e Lazer | N56: =VLOOKUP(L56,Planilha2!$I$2:$K$100,3,FALSE) -> Política Social | O56: Utilidade Pública | U56: =VLOOKUP(B56,Planilha2!$B$2:$D$100,3,FALSE) -> lei-ordinaria | V56: ="/legislatura/" & I56 & "/" & H56 & "/" & U56 & "/" & C56 & "-" & TEXT(D56,"00000") & "-" & H56 & ".md" -> /legislatura/1977-1982/1977/lei-ordinaria/LEI-00013-1977.md | W56: Sim | X56: ="/legislatura/" & I56 & "/" & H56 & "/" & U56 & "/" & C56 & "-" & TEXT(D56,"00000") & "-" & H56 & "c.md" -> /legislatura/1977-1982/1977/lei-ordinaria/LEI-00013-1977c.md | Y56: Não
B57: Lei Ordinária | C57: =VLOOKUP(B57,Planilha2!$B$2:$C$100,2,FALSE) -> LEI | D57: 5 | E57: 28367 | F57: LEI Nº 05 DE 30 DE AGOSTO DE 1977. | G57: Art. 1º Ficam criados dois (02) cargos de Despachante Oficial junto a Prefeitura Municipal, sem ônus para o Município. | H57: =YEAR(E57) -> 1977 | I57: =VLOOKUP(H57,Planilha2!$E$1:$F$100,2,FALSE) -> 1977-1982 | J57: Revogada | K57: Executivo | L57: Cargos e Funções Públicos | M57: =VLOOKUP(L57,Planilha2!$I$2:$K$100,2,FALSE) -> Organização Administrativa | N57: =VLOOKUP(L57,Planilha2!$I$2:$K$100,3,FALSE) -> Administração Pública | O57: Despachante | U57: =VLOOKUP(B57,Planilha2!$B$2:$D$100,3,FALSE) -> lei-ordinaria | V57: ="/legislatura/" & I57 & "/" & H57 & "/" & U57 & "/" & C57 & "-" & TEXT(D57,"00000") & "-" & H57 & ".md" -> /legislatura/1977-1982/1977/lei-ordinaria/LEI-00005-1977.md | W57: Sim | X57: ="/legislatura/" & I57 & "/" & H57 & "/" & U57 & "/" & C57 & "-" & TEXT(D57,"00000") & "-" & H57 & "c.md" -> /legislatura/1977-1982/1977/lei-ordinaria/LEI-00005-1977c.md | Y57: Não
B58: Lei Ordinária | C58: =VLOOKUP(B58,Planilha2!$B$2:$C$100,2,FALSE) -> LEI | D58: 6 | E58: 28367 | F58: LEI Nº 06 DE 30 DE AGOSTO DE 1977. | G58: Art. 1º Fica denominada ALFREDO JOSE MARINS A denominada Rua 20, a que se inicia na rua 11 e termina na Rua 07, bairro da Praia de Araçatiba, 1º distrito deste Município. | H58: =YEAR(E58) -> 1977 | I58: =VLOOKUP(H58,Planilha2!$E$1:$F$100,2,FALSE) -> 1977-1982 | L58: Denominação de Logradouros | M58: =VLOOKUP(L58,Planilha2!$I$2:$K$100,2,FALSE) -> Símbolos e Honrarias | N58: =VLOOKUP(L58,Planilha2!$I$2:$K$100,3,FALSE) -> Organização e Normas Gerais | O58: Nome de Rua | U58: =VLOOKUP(B58,Planilha2!$B$2:$D$100,3,FALSE) -> lei-ordinaria | V58: ="/legislatura/" & I58 & "/" & H58 & "/" & U58 & "/" & C58 & "-" & TEXT(D58,"00000") & "-" & H58 & ".md" -> /legislatura/1977-1982/1977/lei-ordinaria/LEI-00006-1977.md | W58: Sim | X58: ="/legislatura/" & I58 & "/" & H58 & "/" & U58 & "/" & C58 & "-" & TEXT(D58,"00000") & "-" & H58 & "c.md" -> /legislatura/1977-1982/1977/lei-ordinaria/LEI-00006-1977c.md | Y58: Não
B59: Lei Ordinária | C59: =VLOOKUP(B59,Planilha2!$B$2:$C$100,2,FALSE) -> LEI | D59: 4 | E59: 28324 | F59: LEI Nº 04 DE 18 DE JULHO DE 1977. | G59: Art. 1º Ficam ratificados os termos do Convênio firmado entre a Prefeitura Municipal de Maricá–RJ e o Ministério da Aeronáutica, através do Departamento de Aviação Civil, para execução de obras e administração no campo de pouso do Aeroclube da cidade de Maricá. | H59: =YEAR(E59) -> 1977 | I59: =VLOOKUP(H59,Planilha2!$E$1:$F$100,2,FALSE) -> 1977-1982 | K59: Executivo | L59: Obras | M59: =VLOOKUP(L59,Planilha2!$I$2:$K$100,2,FALSE) -> Infraestrutura e Serviços | N59: =VLOOKUP(L59,Planilha2!$I$2:$K$100,3,FALSE) -> Desenvolvimento Urbano e Infraestrutura | O59: Aeroporto | U59: =VLOOKUP(B59,Planilha2!$B$2:$D$100,3,FALSE) -> lei-ordinaria | V59: ="/legislatura/" & I59 & "/" & H59 & "/" & U59 & "/" & C59 & "-" & TEXT(D59,"00000") & "-" & H59 & ".md" -> /legislatura/1977-1982/1977/lei-ordinaria/LEI-00004-1977.md | W59: Sim | X59: ="/legislatura/" & I59 & "/" & H59 & "/" & U59 & "/" & C59 & "-" & TEXT(D59,"00000") & "-" & H59 & "c.md" -> /legislatura/1977-1982/1977/lei-ordinaria/LEI-00004-1977c.md | Y59: Não
B60: Lei Ordinária | C60: =VLOOKUP(B60,Planilha2!$B$2:$C$100,2,FALSE) -> LEI | D60: 7 | E60: 28367 | F60: LEI Nº 07 DE 30 DE AGOSTO DE 1977. | G60: Art. 1º Fica o Poder Executivo Municipal autorizado a abrir, por Decreto, Crédito Especial na importância de Cr$ 564.246,40 – (quinhentos e sessenta e quatro mil, duzentos e quarenta e seis cruzeiros e quarenta centavos), Para atender as despesas de Obras Públicas, com a construção da Ponte sobre o Canal do Boqueirão. | H60: =YEAR(E60) -> 1977 | I60: =VLOOKUP(H60,Planilha2!$E$1:$F$100,2,FALSE) -> 1977-1982 | L60: Crédito Especial | M60: =VLOOKUP(L60,Planilha2!$I$2:$K$100,2,FALSE) -> Crédito Adicional | N60: =VLOOKUP(L60,Planilha2!$I$2:$K$100,3,FALSE) -> Finanças e Economia | U60: =VLOOKUP(B60,Planilha2!$B$2:$D$100,3,FALSE) -> lei-ordinaria | V60: ="/legislatura/" & I60 & "/" & H60 & "/" & U60 & "/" & C60 & "-" & TEXT(D60,"00000") & "-" & H60 & ".md" -> /legislatura/1977-1982/1977/lei-ordinaria/LEI-00007-1977.md | W60: Sim | X60: ="/legislatura/" & I60 & "/" & H60 & "/" & U60 & "/" & C60 & "-" & TEXT(D60,"00000") & "-" & H60 & "c.md" -> /legislatura/1977-1982/1977/lei-ordinaria/LEI-00007-1977c.md | Y60: Não
B61: Lei Ordinária | C61: =VLOOKUP(B61,Planilha2!$B$2:$C$100,2,FALSE) -> LEI | D61: 8 | E61: 28360 | F61: LEI Nº 08 DE 23 DE AGOSTO DE 1977. | G61: Cria exigência de arborização para as áreas destinadas a logradouro / públicas dos novos loteamentos e dá outras previdências. | H61: =YEAR(E61) -> 1977 | I61: =VLOOKUP(H61,Planilha2!$E$1:$F$100,2,FALSE) -> 1977-1982 | L61: Zoneamento, Parcelamento, Uso e Ocupação do Solo | M61: =VLOOKUP(L61,Planilha2!$I$2:$K$100,2,FALSE) -> Planejamento Urbano | N61: =VLOOKUP(L61,Planilha2!$I$2:$K$100,3,FALSE) -> Desenvolvimento Urbano e Infraestrutura | O61: Arborização | U61: =VLOOKUP(B61,Planilha2!$B$2:$D$100,3,FALSE) -> lei-ordinaria | V61: ="/legislatura/" & I61 & "/" & H61 & "/" & U61 & "/" & C61 & "-" & TEXT(D61,"00000") & "-" & H61 & ".md" -> /legislatura/1977-1982/1977/lei-ordinaria/LEI-00008-1977.md | X61: ="/legislatura/" & I61 & "/" & H61 & "/" & U61 & "/" & C61 & "-" & TEXT(D61,"00000") & "-" & H61 & "c.md" -> /legislatura/1977-1982/1977/lei-ordinaria/LEI-00008-1977c.md
C62: =VLOOKUP(B62,Planilha2!$B$2:$C$100,2,FALSE) -> #N/A | H62: =YEAR(E62) -> 1900 | I62: =VLOOKUP(H62,Planilha2!$E$1:$F$100,2,FALSE) -> #N/A | M62: =VLOOKUP(L62,Planilha2!$I$2:$K$100,2,FALSE) -> #N/A | N62: =VLOOKUP(L62,Planilha2!$I$2:$K$100,3,FALSE) -> #N/A | U62: =VLOOKUP(B62,Planilha2!$B$2:$D$100,3,FALSE) -> #N/A | V62: ="/legislatura/" & I62 & "/" & H62 & "/" & U62 & "/" & C62 & "-" & TEXT(D62,"00000") & "-" & H62 & ".md" -> #N/A | X62: ="/legislatura/" & I62 & "/" & H62 & "/" & U62 & "/" & C62 & "-" & TEXT(D62,"00000") & "-" & H62 & "c.md" -> #N/A
C63: =VLOOKUP(B63,Planilha2!$B$2:$C$100,2,FALSE) -> #N/A | H63: =YEAR(E63) -> 1900 | I63: =VLOOKUP(H63,Planilha2!$E$1:$F$100,2,FALSE) -> #N/A | M63: =VLOOKUP(L63,Planilha2!$I$2:$K$100,2,FALSE) -> #N/A | N63: =VLOOKUP(L63,Planilha2!$I$2:$K$100,3,FALSE) -> #N/A | U63: =VLOOKUP(B63,Planilha2!$B$2:$D$100,3,FALSE) -> #N/A | V63: ="/legislatura/" & I63 & "/" & H63 & "/" & U63 & "/" & C63 & "-" & TEXT(D63,"00000") & "-" & H63 & ".md" -> #N/A | X63: ="/legislatura/" & I63 & "/" & H63 & "/" & U63 & "/" & C63 & "-" & TEXT(D63,"00000") & "-" & H63 & "c.md" -> #N/A
C64: =VLOOKUP(B64,Planilha2!$B$2:$C$100,2,FALSE) -> #N/A | H64: =YEAR(E64) -> 1900 | I64: =VLOOKUP(H64,Planilha2!$E$1:$F$100,2,FALSE) -> #N/A | M64: =VLOOKUP(L64,Planilha2!$I$2:$K$100,2,FALSE) -> #N/A | N64: =VLOOKUP(L64,Planilha2!$I$2:$K$100,3,FALSE) -> #N/A | U64: =VLOOKUP(B64,Planilha2!$B$2:$D$100,3,FALSE) -> #N/A | V64: ="/legislatura/" & I64 & "/" & H64 & "/" & U64 & "/" & C64 & "-" & TEXT(D64,"00000") & "-" & H64 & ".md" -> #N/A | X64: ="/legislatura/" & I64 & "/" & H64 & "/" & U64 & "/" & C64 & "-" & TEXT(D64,"00000") & "-" & H64 & "c.md" -> #N/A
...

Sheet Planilha2
A1: =Planilha1!A1 -> id | B1: =Planilha1!B1 -> tipo_norma | C1: =Planilha1!C1 -> cod_norma | D1: pasta | E1: =Planilha1!H1 -> ano | F1: =Planilha1!I1 -> legisltura | G1: =Planilha1!J1 -> status | H1: =Planilha1!K1 -> autor | I1: =Planilha1!L1 -> subcategoria | J1: =Planilha1!M1 -> categoria | K1: =Planilha1!N1 -> tema | L1: =Planilha1!O1 -> palavra-chave | M1: fonte_publicacao | N1: =Planilha1!T1 -> link_publicacao | O1: =Planilha1!V1 -> link_consolidado | P1: =Planilha1!X1 -> link_compilado | Q1: =Planilha1!Y1 -> portal_conso | R1: =Planilha1!Z1 -> obs
B2: Decreto | C2: DEC | D2: decreto | E2: 1977 | F2: 1977-1982 | G2: Anulada | H2: Executivo | I2: Administração Pública Direta | J2: Organização Administrativa | K2: Administração Pública | M2: JOM | Q2: Sim
B3: Emenda à Lei Orgânica | C3: ELO | D3: lei-organica | E3: 1978 | F3: 1977-1982 | G3: Caduca | H3: Legislativo | I3: Administração Pública Indireta | J3: Organização Administrativa | K3: Administração Pública | M3: JOM Especial | Q3: Não
B4: Instrução Normativa | C4: INN | D4: instrucao-normativa | E4: 1979 | F4: 1977-1982 | G4: Em vigor | I4: Agentes Políticos | J4: Agentes Públicos | K4: Administração Pública | M4: Jornal da Região
B5: Lei Complementar | C5: LCM | D5: lei-complementar | E5: 1980 | F5: 1977-1982 | G5: Revogada | I5: Áreas de Preservação e Proteção | J5: Proteção Ambiental | K5: Meio Ambiente e Sustentabilidade
B6: Lei Ordinária | C6: LEI | D6: lei-ordinaria | E6: 1981 | F6: 1977-1982 | G6: Revogada Tacitamente | I6: Assistência Social | J6: Proteção Social | K6: Política Social
B7: Lei Orgânica | C7: LOM | D7: lei-organica | E7: 1982 | F7: 1977-1982 | G7: Suspensa | I7: Calamidade Pública e Emergência Social | J7: Proteção Social | K7: Política Social
B8: Portaria | C8: PTR | D8: portaria | E8: 1983 | F8: 1983-1988 | I8: Cargos e Funções Públicos | J8: Organização Administrativa | K8: Administração Pública
B9: Resolução | C9: RES | D9: resolucao | E9: 1984 | F9: 1983-1988 | I9: Código de Obras | J9: Planejamento Urbano | K9: Desenvolvimento Urbano e Infraestrutura
B10: Resolução da Camara | C10: RCV | D10: resolucao-camara | E10: 1985 | F10: 1983-1988 | I10: Concessão, Permissão e Autorização de Serviços | J10: Serviços Públicos | K10: Administração Pública
E11: 1986 | F11: 1983-1988 | I11: Crédito Especial | J11: Crédito Adicional | K11: Finanças e Economia
E12: 1987 | F12: 1983-1988 | I12: Crédito Extraordinário | J12: Crédito Adicional | K12: Finanças e Economia
E13: 1988 | F13: 1983-1988 | I13: Crédito Suplementar | J13: Crédito Adicional | K13: Finanças e Economia
E14: 1989 | F14: 1989-1992 | I14: Criação, Alteração e Consolidação de Leis Municipais | J14: Processo Legislativo | K14: Organização e Normas Gerais
E15: 1990 | F15: 1989-1992 | I15: Crianças e Adolescentes | J15: Proteção Social | K15: Política Social
E16: 1991 | F16: 1989-1992 | I16: Cultura | J16: Cultura, Esporte e Lazer | K16: Política Social
E17: 1992 | F17: 1989-1992 | I17: Datas Comemorativas e Feriados | J17: Símbolos e Honrarias | K17: Organização e Normas Gerais
E18: 1993 | F18: 1993-1996 | I18: Denominação de Logradouros | J18: Símbolos e Honrarias | K18: Organização e Normas Gerais
E19: 1994 | F19: 1993-1996 | I19: Desenvolvimento Social e Combate à Fome | J19: Proteção Social | K19: Política Social
E20: 1995 | F20: 1993-1996 | I20: Desestatização | J20: Terceiro Setor, Parcerias Público-Privadas e Desestatização | K20: Administração Pública
E21: 1996 | F21: 1993-1996 | I21: Direitos Humanos e Minorias | J21: Proteção Social | K21: Política Social
E22: 1997 | F22: 1997-2000 | I22: Dívida Pública e Operações de Crédito | J22: Finanças e Crédito Público | K22: Finanças e Economia
... E50: 2025 | F50: 2025-2028 | I50: População Indígena | J50: Proteção Social | K50: Política Social
I51: Programas Habitacionais e de Regularização Fundiária | J51: Habitação | K51: Desenvolvimento Urbano e Infraestrutura
I52: Proteção aos Animais e Bem-Estar Animal | J52: Fauna e Flora | K52: Meio Ambiente e Sustentabilidade
I53: Proteção de Dados | J53: Transparência e Governança | K53: Administração Pública
I54: Recursos Hídricos | J54: Proteção Ambiental | K54: Meio Ambiente e Sustentabilidade
I55: Regime Disciplinar | J55: Agentes Públicos | K55: Administração Pública
I56: Regimento Interno | J56: Lei Orgânica e Regimento Interno | K56: Organização e Normas Gerais
I57: Regulamentação e Fiscalização de Serviços | J57: Serviços Públicos | K57: Administração Pública
I58: Resíduos Sólidos e Limpeza Urbana | J58: Infraestrutura e Serviços | K58: Desenvolvimento Urbano e Infraestrutura
I59: Saneamento Básico | J59: Infraestrutura e Serviços | K59: Desenvolvimento Urbano e Infraestrutura
I60: Servidor Público | J60: Agentes Públicos | K60: Administração Pública
I61: Sistema Único de Saúde (SUS) e Rede de Atendimento Local | J61: Saúde | K61: Política Social
I62: Taxas e Contribuições | J62: Tributos | K62: Finanças e Economia
... I72: Zoneamento, Parcelamento, Uso e Ocupação do Solo | J72: Planejamento Urbano | K72: Desenvolvimento Urbano e Infraestrutura
